Traceback (most recent call last):
  File "C:\Users\Charlie\.conda\envs\pythongis\lib\site-packages\jupyter_cache\executors\utils.py", line 58, in single_nb_execution
    executenb(
  File "C:\Users\Charlie\.conda\envs\pythongis\lib\site-packages\nbclient\client.py", line 1265, in execute
    return NotebookClient(nb=nb, resources=resources, km=km, **kwargs).execute()
  File "C:\Users\Charlie\.conda\envs\pythongis\lib\site-packages\jupyter_core\utils\__init__.py", line 160, in wrapped
    return loop.run_until_complete(inner)
  File "C:\Users\Charlie\.conda\envs\pythongis\lib\asyncio\base_events.py", line 642, in run_until_complete
    return future.result()
  File "C:\Users\Charlie\.conda\envs\pythongis\lib\site-packages\nbclient\client.py", line 703, in async_execute
    await self.async_execute_cell(
  File "C:\Users\Charlie\.conda\envs\pythongis\lib\site-packages\nbclient\client.py", line 1021, in async_execute_cell
    await self._check_raise_for_error(cell, cell_index, exec_reply)
  File "C:\Users\Charlie\.conda\envs\pythongis\lib\site-packages\nbclient\client.py", line 915, in _check_raise_for_error
    raise CellExecutionError.from_cell_and_msg(cell, exec_reply_content)
nbclient.exceptions.CellExecutionError: An error occurred while executing the following cell:
------------------
# Ruta del archivo
#uri=r'D:\Charlie\01_Cartografia\catastro.gpkg'

# Lectura como GeoDataFrame
puertas = gpd.read_file(uri, layer='address_points')
------------------

[1;31m---------------------------------------------------------------------------[0m
[1;31mNameError[0m                                 Traceback (most recent call last)
Cell [1;32mIn[2], line 5[0m
[0;32m      1[0m [38;5;66;03m# Ruta del archivo[39;00m
[0;32m      2[0m [38;5;66;03m#uri=r'D:\Charlie\01_Cartografia\catastro.gpkg'[39;00m
[0;32m      3[0m 
[0;32m      4[0m [38;5;66;03m# Lectura como GeoDataFrame[39;00m
[1;32m----> 5[0m puertas [38;5;241m=[39m gpd[38;5;241m.[39mread_file([43muri[49m, layer[38;5;241m=[39m[38;5;124m'[39m[38;5;124maddress_points[39m[38;5;124m'[39m)

[1;31mNameError[0m: name 'uri' is not defined
NameError: name 'uri' is not defined

